Workbook

Sheet Amortissement linéaire
B2: Amortissement Lineaire
B5: Détails de L'immobilisation
B7: Valeur du bien ** | D7: 25562.82 | E7: ** Doit être la valeur hors TVA du bien acheté
B8: Nombre d'années d'amortissement | D8: 5
B9: Date d'acquisition (jj/mm/aaa) | D9: 44743
B10: Date de début d'exercice* (jj/mm/aaaa) | D10: 44562 | E10: *Date complète de début d'exercice de l'année d'acquisition de l'immobilisation. Doit être avant la date d'acquisition de l'immobilisation
B11: Durée d'utilisation 1ère année | D11: =IF(OR(D9="",D10=""),"",(360-(D9-D10))) -> 179
B12: Durée d'utilisation dernière année | D12: =IF(OR(D9="",D10=""),"",360-D11) -> 181
B14: Tableau D'amortissement Linéaire
B16: Année | C16: Valeur comptable Début d'exercice | E16: Annuité d'amortissement | F16: Amortissements cumulés | G16: Valeur nette comptable en fin d'exercice
B17: =IF(OR(D8="",D7="",D11=""),"",1) -> 1 | C17: =IF(D7="","",D7) -> 25562.82 | E17: =IF(OR(B17="",D11=""),"",(D$7/D$8)*D11/360) -> 2542.0804 | F17: =E17 -> 2542.0804 | G17: =IF(B17="","",C17-E17) -> 23020.74
B18: =IF(B17="","",IF(B17+1>D$8+1,"",B17+1)) -> 2 | C18: =IF(B18="","",C17-E17) -> 23020.74 | E18: =IF(B18="","",IF(B18=D$8+1,(D$7/D$8)*(D$12/360),D$7/D$8)) -> 5112.564 | F18: =IF(B18="","",F17+E18) -> 7654.6444 | G18: =IF(B18="","",C18-E18) -> 17908.176
B19: =IF(B18="","",IF(B18+1>D$8+1,"",B18+1)) -> 3 | C19: =IF(B19="","",C18-E18) -> 17908.176 | E19: =IF(B19="","",IF(B19=D$8+1,(D$7/D$8)*(D$12/360),D$7/D$8)) -> 5112.564 | F19: =IF(B19="","",F18+E19) -> 12767.208 | G19: =IF(B19="","",C19-E19) -> 12795.612
B20: =IF(B19="","",IF(B19+1>D$8+1,"",B19+1)) -> 4 | C20: =IF(B20="","",C19-E19) -> 12795.612 | E20: =IF(B20="","",IF(B20=D$8+1,(D$7/D$8)*(D$12/360),D$7/D$8)) -> 5112.564 | F20: =IF(B20="","",F19+E20) -> 17879.772 | G20: =IF(B20="","",C20-E20) -> 7683.0476
B21: =IF(B20="","",IF(B20+1>D$8+1,"",B20+1)) -> 5 | C21: =IF(B21="","",C20-E20) -> 7683.0476 | E21: =IF(B21="","",IF(B21=D$8+1,(D$7/D$8)*(D$12/360),D$7/D$8)) -> 5112.564 | F21: =IF(B21="","",F20+E21) -> 22992.336 | G21: =IF(B21="","",C21-E21) -> 2570.4836
B22: =IF(B21="","",IF(B21+1>D$8+1,"",B21+1)) -> 6 | C22: =IF(B22="","",C21-E21) -> 2570.4836 | E22: =IF(B22="","",IF(B22=D$8+1,(D$7/D$8)*(D$12/360),D$7/D$8)) -> 2570.4836 | F22: =IF(B22="","",F21+E22) -> 25562.82 | G22: =IF(B22="","",C22-E22) -> -2.7284841e-12
B23: =IF(B22="","",IF(B22+1>D$8+1,"",B22+1)) | C23: =IF(B23="","",C22-E22) | E23: =IF(B23="","",IF(B23=D$8+1,(D$7/D$8)*(D$12/360),D$7/D$8)) | F23: =IF(B23="","",F22+E23) | G23: =IF(B23="","",C23-E23)
B24: =IF(B23="","",IF(B23+1>D$8+1,"",B23+1)) | C24: =IF(B24="","",C23-E23) | E24: =IF(B24="","",IF(B24=D$8+1,(D$7/D$8)*(D$12/360),D$7/D$8)) | F24: =IF(B24="","",F23+E24) | G24: =IF(B24="","",C24-E24)
B25: =IF(B24="","",IF(B24+1>D$8+1,"",B24+1)) | C25: =IF(B25="","",C24-E24) | E25: =IF(B25="","",IF(B25=D$8+1,(D$7/D$8)*(D$12/360),D$7/D$8)) | F25: =IF(B25="","",F24+E25) | G25: =IF(B25="","",C25-E25)
B26: =IF(B25="","",IF(B25+1>D$8+1,"",B25+1)) | C26: =IF(B26="","",C25-E25) | E26: =IF(B26="","",IF(B26=D$8+1,(D$7/D$8)*(D$12/360),D$7/D$8)) | F26: =IF(B26="","",F25+E26) | G26: =IF(B26="","",C26-E26)
B27: =IF(B26="","",IF(B26+1>D$8+1,"",B26+1)) | C27: =IF(B27="","",C26-E26) | E27: =IF(B27="","",IF(B27=D$8+1,(D$7/D$8)*(D$12/360),D$7/D$8)) | F27: =IF(B27="","",F26+E27) | G27: =IF(B27="","",C27-E27)

Sheet Amortissement dégressif
B2: Tableau D'amortissement Dégressif
J4: Janvier | K4: 12
B5: Détails de L'immobilisation | G5: Coeficient D'amortissement | J5: Février | K5: 11
J6: Mars | K6: 10
B7: Valeur du bien * | D7: 10000 | E7: * Doit être la valeur hors TVA du bien acheté | G7: Durée d'amortissement | H7: Coef à appliquer | J7: Avril | K7: 9
B8: Nb années d'amortissement | D8: 10 | G8: égale à 3 ou 4 ans | H8: 1.25 | J8: Mai | K8: 8
B9: Mois d'acquisiton | D9: Mars | G9: ègale à 5 ou 6 ans | H9: 1.75 | J9: Juin | K9: 7
B10: Coef à appliquer | D10: =IF(OR(D7="",D8=""),"",IF(D8<5,H8,IF(D8<7,H9,H10))) -> 2.25 | G10: Supérieure à 6 ans | H10: 2.25 | J10: Juillet | K10: 6
B11: Taux d'amortissement dégressif | D11: =IF(OR(D7="",D8=""),"",(1/D8)*D10) -> 0.225 | J11: Août | K11: 5
B12: Nb mois d'utilisation 1ère année | D12: =IF(D9="","",VLOOKUP(D9,J4:K15,2,0)) -> 10 | E12: Si votre année fiscale ne commence pas au 1er janvier, inscrivez manuellement le nombre de mois d'utilisation de votre immobilisation. | J12: Septembre | K12: 4
J13: Octobre | K13: 3
B14: Tableau D'amortissement Linéaire | J14: Novembre | K14: 2
J15: Décembre | K15: 1
B16: Année | C16: Valeur comptable Début d'exercice | E16: Annuité d'amortissement | F16: Amortissements cumulés | G16: Valeur nette comptable en fin d'exercice | H16: Taux linéaire | I16: Nombre d'années restantes
B17: =IF(OR(D8="",D7="",D9=""),"",1) -> 1 | C17: =IF(D7="","",D7) -> 10000 | E17: =IF(B17="","",(IF(D$11>H17,C17*D$11,C17*G17))*D12/12) -> 1875 | F17: =E17 -> 1875 | G17: =IF(B17="","",C17-E17) -> 8125 | H17: =IF(B17="","",1/I17) -> 0.1 | I17: =IF(D8="","",D8) -> 10
B18: =IF(OR(B17="",D$7=""),"",IF(B17+1>D$8,"",B17+1)) -> 2 | C18: =IF(B18="","",C17-E17) -> 8125 | E18: =IF(B18="","",IF(D$11>H18,C18*D$11,C18*H18)) -> 1828.125 | F18: =IF(B18="","",F17+E18) -> 3703.125 | G18: =IF(B18="","",C18-E18) -> 6296.875 | H18: =IF(B18="","",1/I18) -> 0.11111111 | I18: =IF(B18="","",I17-1) -> 9
B19: =IF(OR(B18="",D$7=""),"",IF(B18+1>D$8,"",B18+1)) -> 3 | C19: =IF(B19="","",C18-E18) -> 6296.875 | E19: =IF(B19="","",IF(D$11>H19,C19*D$11,C19*H19)) -> 1416.7969 | F19: =IF(B19="","",F18+E19) -> 5119.9219 | G19: =IF(B19="","",C19-E19) -> 4880.0781 | H19: =IF(B19="","",1/I19) -> 0.125 | I19: =IF(B19="","",I18-1) -> 8
B20: =IF(OR(B19="",D$7=""),"",IF(B19+1>D$8,"",B19+1)) -> 4 | C20: =IF(B20="","",C19-E19) -> 4880.0781 | E20: =IF(B20="","",IF(D$11>H20,C20*D$11,C20*H20)) -> 1098.0176 | F20: =IF(B20="","",F19+E20) -> 6217.9395 | G20: =IF(B20="","",C20-E20) -> 3782.0605 | H20: =IF(B20="","",1/I20) -> 0.14285714 | I20: =IF(B20="","",I19-1) -> 7
B21: =IF(OR(B20="",D$7=""),"",IF(B20+1>D$8,"",B20+1)) -> 5 | C21: =IF(B21="","",C20-E20) -> 3782.0605 | E21: =IF(B21="","",IF(D$11>H21,C21*D$11,C21*H21)) -> 850.96362 | F21: =IF(B21="","",F20+E21) -> 7068.9031 | G21: =IF(B21="","",C21-E21) -> 2931.0969 | H21: =IF(B21="","",1/I21) -> 0.16666667 | I21: =IF(B21="","",I20-1) -> 6
B22: =IF(OR(B21="",D$7=""),"",IF(B21+1>D$8,"",B21+1)) -> 6 | C22: =IF(B22="","",C21-E21) -> 2931.0969 | E22: =IF(B22="","",IF(D$11>H22,C22*D$11,C22*H22)) -> 659.49681 | F22: =IF(B22="","",F21+E22) -> 7728.3999 | G22: =IF(B22="","",C22-E22) -> 2271.6001 | H22: =IF(B22="","",1/I22) -> 0.2 | I22: =IF(B22="","",I21-1) -> 5
B23: =IF(OR(B22="",D$7=""),"",IF(B22+1>D$8,"",B22+1)) -> 7 | C23: =IF(B23="","",C22-E22) -> 2271.6001 | E23: =IF(B23="","",IF(D$11>H23,C23*D$11,C23*H23)) -> 567.90003 | F23: =IF(B23="","",F22+E23) -> 8296.2999 | G23: =IF(B23="","",C23-E23) -> 1703.7001 | H23: =IF(B23="","",1/I23) -> 0.25 | I23: =IF(B23="","",I22-1) -> 4
B24: =IF(OR(B23="",D$7=""),"",IF(B23+1>D$8,"",B23+1)) -> 8 | C24: =IF(B24="","",C23-E23) -> 1703.7001 | E24: =IF(B24="","",IF(D$11>H24,C24*D$11,C24*H24)) -> 567.90003 | F24: =IF(B24="","",F23+E24) -> 8864.1999 | G24: =IF(B24="","",C24-E24) -> 1135.8001 | H24: =IF(B24="","",1/I24) -> 0.33333333 | I24: =IF(B24="","",I23-1) -> 3
B25: =IF(OR(B24="",D$7=""),"",IF(B24+1>D$8,"",B24+1)) -> 9 | C25: =IF(B25="","",C24-E24) -> 1135.8001 | E25: =IF(B25="","",IF(D$11>H25,C25*D$11,C25*H25)) -> 567.90003 | F25: =IF(B25="","",F24+E25) -> 9432.1 | G25: =IF(B25="","",C25-E25) -> 567.90003 | H25: =IF(B25="","",1/I25) -> 0.5 | I25: =IF(B25="","",I24-1) -> 2
B26: =IF(OR(B25="",D$7=""),"",IF(B25+1>D$8,"",B25+1)) -> 10 | C26: =IF(B26="","",C25-E25) -> 567.90003 | E26: =IF(B26="","",IF(D$11>H26,C26*D$11,C26*H26)) -> 567.90003 | F26: =IF(B26="","",F25+E26) -> 10000 | G26: =IF(B26="","",C26-E26) -> 0 | H26: =IF(B26="","",1/I26) -> 1 | I26: =IF(B26="","",I25-1) -> 1

Sheet Saisie lin
B1: NEW LIFE Sàrl | E1: Amortissement Linéaire
B4: Détails de L'immobilisation | E4: VEHICULES MOTEUR
B6: Valeur du bien ** | D6: 25562.82 | E6: Car Avenue - Luxembourg
B7: Nombre d'années d'amortissement | D7: 5
B8: Date d'acquisition (jj/mm/aaa) | D8: 44743
B9: Date de début d'exercice * (jj/mm/aaaa) | D9: 44562
B10: Durée d'utilisation 1ère année | D10: =IF(OR(D8="",D9=""),"",(360-(D8-D9))) -> 179
B11: Durée d'utilisation dernière année | D11: =IF(OR(D8="",D9=""),"",360-D10) -> 181
B13: Tableau D'amortissement Linéaire
B15: Année | C15: Valeur comptable Début d'exercice | E15: Annuité d'amortissement | F15: Amortissements cumulés | G15: Valeur nette comptable en fin d'exercice
B16: =IF(OR(D7="",D6="",D10=""),"",1) -> 1 | C16: =IF(D6="","",D6) -> 25562.82 | E16: =IF(OR(B16="",D10=""),"",(D$6/D$7)*D10/360) -> 2542.0804 | F16: =E16 -> 2542.0804 | G16: =IF(B16="","",C16-E16) -> 23020.74
B17: =IF(B16="","",IF(B16+1>D$7+1,"",B16+1)) -> 2 | C17: =IF(B17="","",C16-E16) -> 23020.74 | E17: =IF(B17="","",IF(B17=D$7+1,(D$6/D$7)*(D$11/360),D$6/D$7)) -> 5112.564 | F17: =IF(B17="","",F16+E17) -> 7654.6444 | G17: =IF(B17="","",C17-E17) -> 17908.176
B18: =IF(B17="","",IF(B17+1>D$7+1,"",B17+1)) -> 3 | C18: =IF(B18="","",C17-E17) -> 17908.176 | E18: =IF(B18="","",IF(B18=D$7+1,(D$6/D$7)*(D$11/360),D$6/D$7)) -> 5112.564 | F18: =IF(B18="","",F17+E18) -> 12767.208 | G18: =IF(B18="","",C18-E18) -> 12795.612
B19: =IF(B18="","",IF(B18+1>D$7+1,"",B18+1)) -> 4 | C19: =IF(B19="","",C18-E18) -> 12795.612 | E19: =IF(B19="","",IF(B19=D$7+1,(D$6/D$7)*(D$11/360),D$6/D$7)) -> 5112.564 | F19: =IF(B19="","",F18+E19) -> 17879.772 | G19: =IF(B19="","",C19-E19) -> 7683.0476
B20: =IF(B19="","",IF(B19+1>D$7+1,"",B19+1)) -> 5 | C20: =IF(B20="","",C19-E19) -> 7683.0476 | E20: =IF(B20="","",IF(B20=D$7+1,(D$6/D$7)*(D$11/360),D$6/D$7)) -> 5112.564 | F20: =IF(B20="","",F19+E20) -> 22992.336 | G20: =IF(B20="","",C20-E20) -> 2570.4836
B21: =IF(B20="","",IF(B20+1>D$7+1,"",B20+1)) -> 6 | C21: =IF(B21="","",C20-E20) -> 2570.4836 | E21: =IF(B21="","",IF(B21=D$7+1,(D$6/D$7)*(D$11/360),D$6/D$7)) -> 2570.4836 | F21: =IF(B21="","",F20+E21) -> 25562.82 | G21: =IF(B21="","",C21-E21) -> -2.7284841e-12
B22: =IF(B21="","",IF(B21+1>D$7+1,"",B21+1)) | C22: =IF(B22="","",C21-E21) | E22: =IF(B22="","",IF(B22=D$7+1,(D$6/D$7)*(D$11/360),D$6/D$7)) | F22: =IF(B22="","",F21+E22) | G22: =IF(B22="","",C22-E22)
B23: =IF(B22="","",IF(B22+1>D$7+1,"",B22+1)) | C23: =IF(B23="","",C22-E22) | E23: =IF(B23="","",IF(B23=D$7+1,(D$6/D$7)*(D$11/360),D$6/D$7)) | F23: =IF(B23="","",F22+E23) | G23: =IF(B23="","",C23-E23)
B24: =IF(B23="","",IF(B23+1>D$7+1,"",B23+1)) | C24: =IF(B24="","",C23-E23) | E24: =IF(B24="","",IF(B24=D$7+1,(D$6/D$7)*(D$11/360),D$6/D$7)) | F24: =IF(B24="","",F23+E24) | G24: =IF(B24="","",C24-E24)
B25: =IF(B24="","",IF(B24+1>D$7+1,"",B24+1)) | C25: =IF(B25="","",C24-E24) | E25: =IF(B25="","",IF(B25=D$7+1,(D$6/D$7)*(D$11/360),D$6/D$7)) | F25: =IF(B25="","",F24+E25) | G25: =IF(B25="","",C25-E25)
B26: =IF(B25="","",IF(B25+1>D$7+1,"",B25+1)) | C26: =IF(B26="","",C25-E25) | E26: =IF(B26="","",IF(B26=D$7+1,(D$6/D$7)*(D$11/360),D$6/D$7)) | F26: =IF(B26="","",F25+E26) | G26: =IF(B26="","",C26-E26)
B28: * Date complète de début d'exercice de l'année d'acquisition de l'immobilisation. Doit être avant la date d'acquisition de l'immobilisation
B29: ** Doit être la valeur hors TVA du bien acheté

Sheet Amm auto
B1: NEW LIFE Sàrl | E1: Amortissement Linéaire
B4: Détails de L'immobilisation | E4: VEHICULES MOTEUR
B6: Valeur du bien ** | D6: =25562.81-8000 -> 17562.81 | E6: Car Avenue - Luxembourg
B7: Nombre d'années d'amortissement | D7: 5
B8: Date d'acquisition (jj/mm/aaa) | D8: 44742
B9: Date de début d'exercice * (jj/mm/aaaa) | D9: 44562
B10: Durée d'utilisation 1ère année | D10: =IF(OR(D8="",D9=""),"",(360-(D8-D9))) -> 180
B11: Durée d'utilisation dernière année | D11: =IF(OR(D8="",D9=""),"",360-D10) -> 180
B13: Tableau D'amortissement Linéaire
B15: Année | C15: Valeur comptable Début d'exercice | E15: Annuité d'amortissement | F15: Amortissements cumulés | G15: Valeur nette comptable en fin d'exercice
B16: =IF(OR(D7="",D6="",D10=""),"",1) -> 1 | C16: =IF(D6="","",D6) -> 17562.81 | E16: =IF(OR(B16="",D10=""),"",(D$6/D$7)*D10/360) -> 1756.281 | F16: =E16 -> 1756.281 | G16: =IF(B16="","",C16-E16) -> 15806.529
B17: =IF(B16="","",IF(B16+1>D$7+1,"",B16+1)) -> 2 | C17: =IF(B17="","",C16-E16) -> 15806.529 | E17: =IF(B17="","",IF(B17=D$7+1,(D$6/D$7)*(D$11/360),D$6/D$7)) -> 3512.562 | F17: =IF(B17="","",F16+E17) -> 5268.843 | G17: =IF(B17="","",C17-E17) -> 12293.967
B18: =IF(B17="","",IF(B17+1>D$7+1,"",B17+1)) -> 3 | C18: =IF(B18="","",C17-E17) -> 12293.967 | E18: =IF(B18="","",IF(B18=D$7+1,(D$6/D$7)*(D$11/360),D$6/D$7)) -> 3512.562 | F18: =IF(B18="","",F17+E18) -> 8781.405 | G18: =IF(B18="","",C18-E18) -> 8781.405
B19: =IF(B18="","",IF(B18+1>D$7+1,"",B18+1)) -> 4 | C19: =IF(B19="","",C18-E18) -> 8781.405 | E19: =IF(B19="","",IF(B19=D$7+1,(D$6/D$7)*(D$11/360),D$6/D$7)) -> 3512.562 | F19: =IF(B19="","",F18+E19) -> 12293.967 | G19: =IF(B19="","",C19-E19) -> 5268.843
B20: =IF(B19="","",IF(B19+1>D$7+1,"",B19+1)) -> 5 | C20: =IF(B20="","",C19-E19) -> 5268.843 | E20: =IF(B20="","",IF(B20=D$7+1,(D$6/D$7)*(D$11/360),D$6/D$7)) -> 3512.562 | F20: =IF(B20="","",F19+E20) -> 15806.529 | G20: =IF(B20="","",C20-E20) -> 1756.281
B21: =IF(B20="","",IF(B20+1>D$7+1,"",B20+1)) -> 6 | C21: =IF(B21="","",C20-E20) -> 1756.281 | E21: =IF(B21="","",IF(B21=D$7+1,(D$6/D$7)*(D$11/360),D$6/D$7)) -> 1756.281 | F21: =IF(B21="","",F20+E21) -> 17562.81 | G21: =IF(B21="","",C21-E21) -> 2.2737368e-13
B22: =IF(B21="","",IF(B21+1>D$7+1,"",B21+1)) | C22: =IF(B22="","",C21-E21) | E22: =IF(B22="","",IF(B22=D$7+1,(D$6/D$7)*(D$11/360),D$6/D$7)) | F22: =IF(B22="","",F21+E22) | G22: =IF(B22="","",C22-E22)
B23: =IF(B22="","",IF(B22+1>D$7+1,"",B22+1)) | C23: =IF(B23="","",C22-E22) | E23: =IF(B23="","",IF(B23=D$7+1,(D$6/D$7)*(D$11/360),D$6/D$7)) | F23: =IF(B23="","",F22+E23) | G23: =IF(B23="","",C23-E23)
B24: =IF(B23="","",IF(B23+1>D$7+1,"",B23+1)) | C24: =IF(B24="","",C23-E23) | E24: =IF(B24="","",IF(B24=D$7+1,(D$6/D$7)*(D$11/360),D$6/D$7)) | F24: =IF(B24="","",F23+E24) | G24: =IF(B24="","",C24-E24)
B25: =IF(B24="","",IF(B24+1>D$7+1,"",B24+1)) | C25: =IF(B25="","",C24-E24) | E25: =IF(B25="","",IF(B25=D$7+1,(D$6/D$7)*(D$11/360),D$6/D$7)) | F25: =IF(B25="","",F24+E25) | G25: =IF(B25="","",C25-E25)
B26: =IF(B25="","",IF(B25+1>D$7+1,"",B25+1)) | C26: =IF(B26="","",C25-E25) | E26: =IF(B26="","",IF(B26=D$7+1,(D$6/D$7)*(D$11/360),D$6/D$7)) | F26: =IF(B26="","",F25+E26) | G26: =IF(B26="","",C26-E26)
B28: * Date complète de début d'exercice de l'année d'acquisition de l'immobilisation. Doit être avant la date d'acquisition de l'immobilisation
B29: ** Doit être la valeur hors TVA du bien acheté

Sheet AMM A
C2: NEW LIFE Sàrl - Luxembourg | I2: 2025 | J2: Tableau d'Amortissement Linéaire | Q2: TOTALI
C4: SOFTWARE
B6: Nr | C6: Valeur du bien | D6: Nombre années amortissement | E6: Date acquisition | F6: Date début exercise | H6: Durée utilisation 1er année | I6: Durée utilisation dernière année | J6: Nr années | K6: Année | L6: Valeur comptable début d'exercise | M6: Annuité d'amortissement | N6: Amortissements cumulés | O6: Valeur nette comptable en fin d'exercice | Q6: Année | R6: Valeur comptable début d'exercise | S6: Annuité d'amortissement | T6: Amortissements cumulés | U6: Valeur nette comptable en fin d'exercice
B7: 1 | C7: 1007.2 | D7: 3 | E7: 45204 | F7: 44927 | G7: =YEAR(F7) -> 2023 | H7: =IF(OR(E7="",F7=""),"",(360-(E7-F7))) -> 83 | I7: =IF(OR(E7="",F7=""),"",360-H7) -> 277 | J7: =IF(OR(D7="",C7="",H7=""),"",1) -> 1 | K7: =IF(G7="","",G7) -> 2023 | L7: =IF(C7="","",C7) -> 1007.2 | M7: =IF(OR(J7="",H7=""),"",(C$7/D$7)*H7/360) -> 77.405185 | N7: =M7 -> 77.405185 | O7: =IF(J7="","",L7-M7) -> 929.79481 | Q7: 2022 | R7: =SUMIF($K$7:$K$61,Q7,$L$7:$L$61) -> 0 | S7: =SUMIF($K$7:$K$61,Q7,$M$7:$M$61) -> 0 | T7: =SUMIF($K$7:$K$61,Q7,$N$7:$N$61) -> 0 | U7: =SUMIF($K$7:$K$61,Q7,$O$7:$O$61) -> 0
C8: Pak Man - Hong Kong | E8: Bureautique | J8: =IF(J7="","",IF(J7+1>D$7+1,"",J7+1)) -> 2 | K8: =IF(J8="","",K7+1) -> 2024 | L8: =IF(J8="","",L7-M7) -> 929.79481 | M8: =IF(J8="","",IF(J8=D$7+1,(C$7/D$7)*(I$7/360),C$7/D$7)) -> 335.73333 | N8: =IF(J8="","",N7+M8) -> 413.13852 | O8: =IF(J8="","",L8-M8) -> 594.06148 | Q8: =Q7+1 -> 2023 | R8: =SUMIF($K$7:$K$61,Q8,$L$7:$L$61) -> 4391.65 | S8: =SUMIF($K$7:$K$61,Q8,$M$7:$M$61) -> 195.97162 | T8: =SUMIF($K$7:$K$61,Q8,$N$7:$N$61) -> 195.97162 | U8: =SUMIF($K$7:$K$61,Q8,$O$7:$O$61) -> 4195.6784
J9: =IF(J8="","",IF(J8+1>D$7+1,"",J8+1)) -> 3 | K9: =IF(J9="","",K8+1) -> 2025 | L9: =IF(J9="","",L8-M8) -> 594.06148 | M9: =IF(J9="","",IF(J9=D$7+1,(C$7/D$7)*(I$7/360),C$7/D$7)) -> 335.73333 | N9: =IF(J9="","",N8+M9) -> 748.87185 | O9: =IF(J9="","",L9-M9) -> 258.32815 | Q9: =Q8+1 -> 2024 | R9: =SUMIF($K$7:$K$61,Q9,$L$7:$L$61) -> 7198.9384 | S9: =SUMIF($K$7:$K$61,Q9,$M$7:$M$61) -> 2161.8632 | T9: =SUMIF($K$7:$K$61,Q9,$N$7:$N$61) -> 2357.8348 | U9: =SUMIF($K$7:$K$61,Q9,$O$7:$O$61) -> 5037.0752
J10: =IF(J9="","",IF(J9+1>D$7+1,"",J9+1)) -> 4 | K10: =IF(J10="","",K9+1) -> 2026 | L10: =IF(J10="","",L9-M9) -> 258.32815 | M10: =IF(J10="","",IF(J10=D$7+1,(C$7/D$7)*(I$7/360),C$7/D$7)) -> 258.32815 | N10: =IF(J10="","",N9+M10) -> 1007.2 | O10: =IF(J10="","",L10-M10) -> -5.6843419e-14 | Q10: =Q9+1 -> 2025 | R10: =SUMIF($K$7:$K$61,Q10,$L$7:$L$61) -> 5037.0752 | S10: =SUMIF($K$7:$K$61,Q10,$M$7:$M$61) -> 2464.97 | T10: =SUMIF($K$7:$K$61,Q10,$N$7:$N$61) -> 4822.8048 | U10: =SUMIF($K$7:$K$61,Q10,$O$7:$O$61) -> 2572.1052
J11: =IF(J10="","",IF(J10+1>D$7+1,"",J10+1)) | K11: =IF(J11="","",K10+1) | L11: =IF(J11="","",L10-M10) | M11: =IF(J11="","",IF(J11=D$7+1,(C$7/D$7)*(I$7/360),C$7/D$7)) | N11: =IF(J11="","",N10+M11) | O11: =IF(J11="","",L11-M11) | Q11: =Q10+1 -> 2026 | R11: =SUMIF($K$7:$K$61,Q11,$L$7:$L$61) -> 2572.1052 | S11: =SUMIF($K$7:$K$61,Q11,$M$7:$M$61) -> 2268.9984 | T11: =SUMIF($K$7:$K$61,Q11,$N$7:$N$61) -> 7091.8032 | U11: =SUMIF($K$7:$K$61,Q11,$O$7:$O$61) -> 303.1068
J12: =IF(J11="","",IF(J11+1>D$7+1,"",J11+1)) | K12: =IF(J12="","",K11+1) | L12: =IF(J12="","",L11-M11) | M12: =IF(J12="","",IF(J12=D$7+1,(C$7/D$7)*(I$7/360),C$7/D$7)) | N12: =IF(J12="","",N11+M12) | O12: =IF(J12="","",L12-M12) | Q12: =Q11+1 -> 2027 | R12: =SUMIF($K$7:$K$61,Q12,$L$7:$L$61) -> 303.1068 | S12: =SUMIF($K$7:$K$61,Q12,$M$7:$M$61) -> 303.1068 | T12: =SUMIF($K$7:$K$61,Q12,$N$7:$N$61) -> 3003.26 | U12: =SUMIF($K$7:$K$61,Q12,$O$7:$O$61) -> 1.7053026e-13
Q13: =Q12+1 -> 2028 | R13: =SUMIF($K$7:$K$61,Q13,$L$7:$L$61) -> 0 | S13: =SUMIF($K$7:$K$61,Q13,$M$7:$M$61) -> 0 | T13: =SUMIF($K$7:$K$61,Q13,$N$7:$N$61) -> 0 | U13: =SUMIF($K$7:$K$61,Q13,$O$7:$O$61) -> 0
B14: =B7+1 -> 2 | C14: 1200.77 | D14: 3 | E14: 45204 | F14: 44927 | G14: =YEAR(F14) -> 2023 | H14: =IF(OR(E14="",F14=""),"",(360-(E14-F14))) -> 83 | I14: =IF(OR(E14="",F14=""),"",360-H14) -> 277 | J14: =IF(OR(D14="",C14="",H14=""),"",1) -> 1 | K14: =IF(G14="","",G14) -> 2023 | L14: =IF(C14="","",C14) -> 1200.77 | M14: =IF(OR(J14="",H14=""),"",(C$14/D$14)*H14/360) -> 92.281398 | N14: =M14 -> 92.281398 | O14: =IF(J14="","",L14-M14) -> 1108.4886 | Q14: =Q13+1 -> 2029 | R14: =SUMIF($K$7:$K$61,Q14,$L$7:$L$61) -> 0 | S14: =SUMIF($K$7:$K$61,Q14,$M$7:$M$61) -> 0 | T14: =SUMIF($K$7:$K$61,Q14,$N$7:$N$61) -> 0 | U14: =SUMIF($K$7:$K$61,Q14,$O$7:$O$61) -> 0
C15: Pak Man - Hong Kong | E15: Bureautique | J15: =IF(J14="","",IF(J14+1>D$14+1,"",J14+1)) -> 2 | K15: =IF(J15="","",K14+1) -> 2024 | L15: =IF(J15="","",L14-M14) -> 1108.4886 | M15: =IF(J15="","",IF(J15=D$14+1,(C$14/D$14)*(I$14/360),C$14/D$14)) -> 400.25667 | N15: =IF(J15="","",N14+M15) -> 492.53806 | O15: =IF(J15="","",L15-M15) -> 708.23194 | Q15: =Q14+1 -> 2030 | R15: =SUMIF($K$7:$K$61,Q15,$L$7:$L$61) -> 0 | S15: =SUMIF($K$7:$K$61,Q15,$M$7:$M$61) -> 0 | T15: =SUMIF($K$7:$K$61,Q15,$N$7:$N$61) -> 0 | U15: =SUMIF($K$7:$K$61,Q15,$O$7:$O$61) -> 0
J16: =IF(J15="","",IF(J15+1>D$14+1,"",J15+1)) -> 3 | K16: =IF(J16="","",K15+1) -> 2025 | L16: =IF(J16="","",L15-M15) -> 708.23194 | M16: =IF(J16="","",IF(J16=D$14+1,(C$14/D$14)*(I$14/360),C$14/D$14)) -> 400.25667 | N16: =IF(J16="","",N15+M16) -> 892.79473 | O16: =IF(J16="","",L16-M16) -> 307.97527
J17: =IF(J16="","",IF(J16+1>D$14+1,"",J16+1)) -> 4 | K17: =IF(J17="","",K16+1) -> 2026 | L17: =IF(J17="","",L16-M16) -> 307.97527 | M17: =IF(J17="","",IF(J17=D$14+1,(C$14/D$14)*(I$14/360),C$14/D$14)) -> 307.97527 | N17: =IF(J17="","",N16+M17) -> 1200.77 | O17: =IF(J17="","",L17-M17) -> 0
J18: =IF(J17="","",IF(J17+1>D$14+1,"",J17+1)) | K18: =IF(J18="","",K17+1) | L18: =IF(J18="","",L17-M17) | M18: =IF(J18="","",IF(J18=D$14+1,(C$14/D$14)*(I$14/360),C$14/D$14)) | N18: =IF(J18="","",N17+M18) | O18: =IF(J18="","",L18-M18)
J19: =IF(J18="","",IF(J18+1>D$14+1,"",J18+1)) | K19: =IF(J19="","",K18+1) | L19: =IF(J19="","",L18-M18) | M19: =IF(J19="","",IF(J19=D$14+1,(C$14/D$14)*(I$14/360),C$14/D$14)) | N19: =IF(J19="","",N18+M19) | O19: =IF(J19="","",L19-M19)
B21: =B14+1 -> 3 | C21: 2183.68 | D21: 3 | E21: 45274 | F21: 44927 | G21: =YEAR(F21) -> 2023 | H21: =IF(OR(E21="",F21=""),"",(360-(E21-F21))) -> 13 | I21: =IF(OR(E21="",F21=""),"",360-H21) -> 347 | J21: =IF(OR(D21="",C21="",H21=""),"",1) -> 1 | K21: =IF(G21="","",G21) -> 2023 | L21: =IF(C21="","",C21) -> 2183.68 | M21: =IF(OR(J21="",H21=""),"",(C$21/D$21)*H21/360) -> 26.285037 | N21: =M21 -> 26.285037 | O21: =IF(J21="","",L21-M21) -> 2157.395
J22: =IF(J21="","",IF(J21+1>D$21+1,"",J21+1)) -> 2 | K22: =IF(J22="","",K21+1) -> 2024 | L22: =IF(J22="","",L21-M21) -> 2157.395 | M22: =IF(J22="","",IF(J22=D$21+1,(C$21/D$21)*(I$21/360),C$21/D$21)) -> 727.89333 | N22: =IF(J22="","",N21+M22) -> 754.17837 | O22: =IF(J22="","",L22-M22) -> 1429.5016
J23: =IF(J22="","",IF(J22+1>D$21+1,"",J22+1)) -> 3 | K23: =IF(J23="","",K22+1) -> 2025 | L23: =IF(J23="","",L22-M22) -> 1429.5016 | M23: =IF(J23="","",IF(J23=D$21+1,(C$21/D$21)*(I$21/360),C$21/D$21)) -> 727.89333 | N23: =IF(J23="","",N22+M23) -> 1482.0717 | O23: =IF(J23="","",L23-M23) -> 701.6083
J24: =IF(J23="","",IF(J23+1>D$21+1,"",J23+1)) -> 4 | K24: =IF(J24="","",K23+1) -> 2026 | L24: =IF(J24="","",L23-M23) -> 701.6083 | M24: =IF(J24="","",IF(J24=D$21+1,(C$21/D$21)*(I$21/360),C$21/D$21)) -> 701.6083 | N24: =IF(J24="","",N23+M24) -> 2183.68 | O24: =IF(J24="","",L24-M24) -> -2.2737368e-13
J25: =IF(J24="","",IF(J24+1>D$21+1,"",J24+1)) | K25: =IF(J25="","",K24+1) | L25: =IF(J25="","",L24-M24) | M25: =IF(J25="","",IF(J25=D$21+1,(C$21/D$21)*(I$21/360),C$21/D$21)) | N25: =IF(J25="","",N24+M25) | O25: =IF(J25="","",L25-M25)
J26: =IF(J25="","",IF(J25+1>D$21+1,"",J25+1)) | K26: =IF(J26="","",K25+1) | L26: =IF(J26="","",L25-M25) | M26: =IF(J26="","",IF(J26=D$21+1,(C$21/D$21)*(I$21/360),C$21/D$21)) | N26: =IF(J26="","",N25+M26) | O26: =IF(J26="","",L26-M26)
B28: =B21+1 -> 4 | C28: 3003.26 | D28: 3 | E28: 45401 | F28: 45292 | G28: =YEAR(F28) -> 2024 | H28: =IF(OR(E28="",F28=""),"",(360-(E28-F28))) -> 251 | I28: =IF(OR(E28="",F28=""),"",360-H28) -> 109 | J28: =IF(OR(D28="",C28="",H28=""),"",1) -> 1 | K28: =IF(G28="","",G28) -> 2024 | L28: =IF(C28="","",C28) -> 3003.26 | M28: =IF(OR(J28="",H28=""),"",(C$28/D$28)*H28/360) -> 697.97987 | N28: =M28 -> 697.97987 | O28: =IF(J28="","",L28-M28) -> 2305.2801
J29: =IF(J28="","",IF(J28+1>D$28+1,"",J28+1)) -> 2 | K29: =IF(J29="","",K28+1) -> 2025 | L29: =IF(J29="","",L28-M28) -> 2305.2801 | M29: =IF(J29="","",IF(J29=D$28+1,(C$28/D$28)*(I$28/360),C$28/D$28)) -> 1001.0867 | N29: =IF(J29="","",N28+M29) -> 1699.0665 | O29: =IF(J29="","",L29-M29) -> 1304.1935
J30: =IF(J29="","",IF(J29+1>D$28+1,"",J29+1)) -> 3 | K30: =IF(J30="","",K29+1) -> 2026 | L30: =IF(J30="","",L29-M29) -> 1304.1935 | M30: =IF(J30="","",IF(J30=D$28+1,(C$28/D$28)*(I$28/360),C$28/D$28)) -> 1001.0867 | N30: =IF(J30="","",N29+M30) -> 2700.1532 | O30: =IF(J30="","",L30-M30) -> 303.1068
J31: =IF(J30="","",IF(J30+1>D$28+1,"",J30+1)) -> 4 | K31: =IF(J31="","",K30+1) -> 2027 | L31: =IF(J31="","",L30-M30) -> 303.1068 | M31: =IF(J31="","",IF(J31=D$28+1,(C$28/D$28)*(I$28/360),C$28/D$28)) -> 303.1068 | N31: =IF(J31="","",N30+M31) -> 3003.26 | O31: =IF(J31="","",L31-M31) -> 1.7053026e-13
J32: =IF(J31="","",IF(J31+1>D$28+1,"",J31+1)) | K32: =IF(J32="","",K31+1) | L32: =IF(J32="","",L31-M31) | M32: =IF(J32="","",IF(J32=D$28+1,(C$28/D$28)*(I$28/360),C$28/D$28)) | N32: =IF(J32="","",N31+M32) | O32: =IF(J32="","",L32-M32)
J33: =IF(J32="","",IF(J32+1>D$28+1,"",J32+1)) | K33: =IF(J33="","",K32+1) | L33: =IF(J33="","",L32-M32) | M33: =IF(J33="","",IF(J33=D$28+1,(C$28/D$28)*(I$28/360),C$28/D$28)) | N33: =IF(J33="","",N32+M33) | O33: =IF(J33="","",L33-M33)
B35: =B28+1 -> 5 | G35: =YEAR(F35) -> 1900 | H35: =IF(OR(E35="",F35=""),"",(360-(E35-F35))) | I35: =IF(OR(E35="",F35=""),"",360-H35) | J35: =IF(OR(D35="",C35="",H35=""),"",1) | K35: =IF(G35="","",G35) -> 1900 | L35: =IF(C35="","",C35) | M35: =IF(OR(J35="",H35=""),"",(C$35/D$35)*H35/360) | N35: =M35 | O35: =IF(J35="","",L35-M35)
J36: =IF(J35="","",IF(J35+1>D$35+1,"",J35+1)) | K36: =IF(J36="","",K35+1) | L36: =IF(J36="","",L35-M35) | M36: =IF(J36="","",IF(J36=D$35+1,(C$35/D$35)*(I$35/360),C$35/D$7)) | N36: =IF(J36="","",N35+M36) | O36: =IF(J36="","",L36-M36)
J37: =IF(J36="","",IF(J36+1>D$35+1,"",J36+1)) | K37: =IF(J37="","",K36+1) | L37: =IF(J37="","",L36-M36) | M37: =IF(J37="","",IF(J37=D$35+1,(C$35/D$35)*(I$35/360),C$35/D$7)) | N37: =IF(J37="","",N36+M37) | O37: =IF(J37="","",L37-M37)
J38: =IF(J37="","",IF(J37+1>D$35+1,"",J37+1)) | K38: =IF(J38="","",K37+1) | L38: =IF(J38="","",L37-M37) | M38: =IF(J38="","",IF(J38=D$35+1,(C$35/D$35)*(I$35/360),C$35/D$7)) | N38: =IF(J38="","",N37+M38) | O38: =IF(J38="","",L38-M38)
J39: =IF(J38="","",IF(J38+1>D$35+1,"",J38+1)) | K39: =IF(J39="","",K38+1) | L39: =IF(J39="","",L38-M38) | M39: =IF(J39="","",IF(J39=D$35+1,(C$35/D$35)*(I$35/360),C$35/D$7)) | N39: =IF(J39="","",N38+M39) | O39: =IF(J39="","",L39-M39)
J40: =IF(J39="","",IF(J39+1>D$35+1,"",J39+1)) | K40: =IF(J40="","",K39+1) | L40: =IF(J40="","",L39-M39) | M40: =IF(J40="","",IF(J40=D$35+1,(C$35/D$35)*(I$35/360),C$35/D$7)) | N40: =IF(J40="","",N39+M40) | O40: =IF(J40="","",L40-M40)
B42: =B35+1 -> 6 | G42: =YEAR(F42) -> 1900 | H42: =IF(OR(E42="",F42=""),"",(360-(E42-F42))) | I42: =IF(OR(E42="",F42=""),"",360-H42) | J42: =IF(OR(D42="",C42="",H42=""),"",1) | K42: =IF(G42="","",G42) -> 1900 | L42: =IF(C42="","",C42) | M42: =IF(OR(J42="",H42=""),"",(C$42/D$42)*H42/360) | N42: =M42 | O42: =IF(J42="","",L42-M42)
J43: =IF(J42="","",IF(J42+1>D$42+1,"",J42+1)) | K43: =IF(J43="","",K42+1) | L43: =IF(J43="","",L42-M42) | M43: =IF(J43="","",IF(J43=D$42+1,(C$42/D$42)*(I$42/360),C$42/D$42)) | N43: =IF(J43="","",N42+M43) | O43: =IF(J43="","",L43-M43)
J44: =IF(J43="","",IF(J43+1>D$42+1,"",J43+1)) | K44: =IF(J44="","",K43+1) | L44: =IF(J44="","",L43-M43) | M44: =IF(J44="","",IF(J44=D$42+1,(C$42/D$42)*(I$42/360),C$42/D$42)) | N44: =IF(J44="","",N43+M44) | O44: =IF(J44="","",L44-M44)
J45: =IF(J44="","",IF(J44+1>D$42+1,"",J44+1)) | K45: =IF(J45="","",K44+1) | L45: =IF(J45="","",L44-M44) | M45: =IF(J45="","",IF(J45=D$42+1,(C$42/D$42)*(I$42/360),C$42/D$42)) | N45: =IF(J45="","",N44+M45) | O45: =IF(J45="","",L45-M45)
J46: =IF(J45="","",IF(J45+1>D$42+1,"",J45+1)) | K46: =IF(J46="","",K45+1) | L46: =IF(J46="","",L45-M45) | M46: =IF(J46="","",IF(J46=D$42+1,(C$42/D$42)*(I$42/360),C$42/D$42)) | N46: =IF(J46="","",N45+M46) | O46: =IF(J46="","",L46-M46)
J47: =IF(J46="","",IF(J46+1>D$42+1,"",J46+1)) | K47: =IF(J47="","",K46+1) | L47: =IF(J47="","",L46-M46) | M47: =IF(J47="","",IF(J47=D$42+1,(C$42/D$42)*(I$42/360),C$42/D$42)) | N47: =IF(J47="","",N46+M47) | O47: =IF(J47="","",L47-M47)
...

Sheet AMM B
C2: NEW LIFE Sàrl - Luxembourg | I2: 2025 | J2: Tableau d'Amortissement Linéaire | Q2: TOTALI
B4: B | C4: VEHICULES MOTEUR
B6: Nr | C6: Valeur du bien | D6: Nombre années amortissement | E6: Date acquisition | F6: Date début exercise | H6: Durée utilisation 1er année | I6: Durée utilisation dernière année | J6: Nr années | K6: Année | L6: Valeur comptable début d'exercise | M6: Annuité d'amortissement | N6: Amortissements cumulés | O6: Valeur nette comptable en fin d'exercice | Q6: Année | R6: Valeur comptable début d'exercise | S6: Annuité d'amortissement | T6: Amortissements cumulés | U6: Valeur nette comptable en fin d'exercice
B7: 1 | C7: =25562.82-8000 -> 17562.82 | D7: 5 | E7: 44742 | F7: 44562 | G7: =YEAR(F7) -> 2022 | H7: =IF(OR(E7="",F7=""),"",(360-(E7-F7))) -> 180 | I7: =IF(OR(E7="",F7=""),"",360-H7) -> 180 | J7: =IF(OR(D7="",C7="",H7=""),"",1) -> 1 | K7: =IF(G7="","",G7) -> 2022 | L7: =IF(C7="","",C7) -> 17562.82 | M7: =IF(OR(J7="",H7=""),"",(C$7/D$7)*H7/360) -> 1756.282 | N7: =M7 -> 1756.282 | O7: =IF(J7="","",L7-M7) -> 15806.538 | Q7: 2022 | R7: =SUMIF($K$7:$K$61,Q7,$L$7:$L$61) -> 17562.82 | S7: =SUMIF($K$7:$K$61,Q7,$M$7:$M$61) -> 1756.282 | T7: =SUMIF($K$7:$K$61,Q7,$N$7:$N$61) -> 1756.282 | U7: =SUMIF($K$7:$K$61,Q7,$O$7:$O$61) -> 15806.538
C8: Car Avenue Peugeot Luxembourg | E8: Vehicule moteur | J8: =IF(J7="","",IF(J7+1>D$7+1,"",J7+1)) -> 2 | K8: =IF(J8="","",K7+1) -> 2023 | L8: =IF(J8="","",L7-M7) -> 15806.538 | M8: =IF(J8="","",IF(J8=D$7+1,(C$7/D$7)*(I$7/360),C$7/D$7)) -> 3512.564 | N8: =IF(J8="","",N7+M8) -> 5268.846 | O8: =IF(J8="","",L8-M8) -> 12293.974 | Q8: =Q7+1 -> 2023 | R8: =SUMIF($K$7:$K$61,Q8,$L$7:$L$61) -> 15806.538 | S8: =SUMIF($K$7:$K$61,Q8,$M$7:$M$61) -> 3512.564 | T8: =SUMIF($K$7:$K$61,Q8,$N$7:$N$61) -> 5268.846 | U8: =SUMIF($K$7:$K$61,Q8,$O$7:$O$61) -> 12293.974
J9: =IF(J8="","",IF(J8+1>D$7+1,"",J8+1)) -> 3 | K9: =IF(J9="","",K8+1) -> 2024 | L9: =IF(J9="","",L8-M8) -> 12293.974 | M9: =IF(J9="","",IF(J9=D$7+1,(C$7/D$7)*(I$7/360),C$7/D$7)) -> 3512.564 | N9: =IF(J9="","",N8+M9) -> 8781.41 | O9: =IF(J9="","",L9-M9) -> 8781.41 | Q9: =Q8+1 -> 2024 | R9: =SUMIF($K$7:$K$61,Q9,$L$7:$L$61) -> 12293.974 | S9: =SUMIF($K$7:$K$61,Q9,$M$7:$M$61) -> 3512.564 | T9: =SUMIF($K$7:$K$61,Q9,$N$7:$N$61) -> 8781.41 | U9: =SUMIF($K$7:$K$61,Q9,$O$7:$O$61) -> 8781.41
J10: =IF(J9="","",IF(J9+1>D$7+1,"",J9+1)) -> 4 | K10: =IF(J10="","",K9+1) -> 2025 | L10: =IF(J10="","",L9-M9) -> 8781.41 | M10: =IF(J10="","",IF(J10=D$7+1,(C$7/D$7)*(I$7/360),C$7/D$7)) -> 3512.564 | N10: =IF(J10="","",N9+M10) -> 12293.974 | O10: =IF(J10="","",L10-M10) -> 5268.846 | Q10: =Q9+1 -> 2025 | R10: =SUMIF($K$7:$K$61,Q10,$L$7:$L$61) -> 8781.41 | S10: =SUMIF($K$7:$K$61,Q10,$M$7:$M$61) -> 3512.564 | T10: =SUMIF($K$7:$K$61,Q10,$N$7:$N$61) -> 12293.974 | U10: =SUMIF($K$7:$K$61,Q10,$O$7:$O$61) -> 5268.846
J11: =IF(J10="","",IF(J10+1>D$7+1,"",J10+1)) -> 5 | K11: =IF(J11="","",K10+1) -> 2026 | L11: =IF(J11="","",L10-M10) -> 5268.846 | M11: =IF(J11="","",IF(J11=D$7+1,(C$7/D$7)*(I$7/360),C$7/D$7)) -> 3512.564 | N11: =IF(J11="","",N10+M11) -> 15806.538 | O11: =IF(J11="","",L11-M11) -> 1756.282 | Q11: =Q10+1 -> 2026 | R11: =SUMIF($K$7:$K$61,Q11,$L$7:$L$61) -> 39196.176 | S11: =SUMIF($K$7:$K$61,Q11,$M$7:$M$61) -> 8601.6635 | T11: =SUMIF($K$7:$K$61,Q11,$N$7:$N$61) -> 20895.638 | U11: =SUMIF($K$7:$K$61,Q11,$O$7:$O$61) -> 30594.513
J12: =IF(J11="","",IF(J11+1>D$7+1,"",J11+1)) -> 6 | K12: =IF(J12="","",K11+1) -> 2027 | L12: =IF(J12="","",L11-M11) -> 1756.282 | M12: =IF(J12="","",IF(J12=D$7+1,(C$7/D$7)*(I$7/360),C$7/D$7)) -> 1756.282 | N12: =IF(J12="","",N11+M12) -> 17562.82 | O12: =IF(J12="","",L12-M12) -> -2.2737368e-13 | Q12: =Q11+1 -> 2027 | R12: =SUMIF($K$7:$K$61,Q12,$L$7:$L$61) -> 30594.513 | S12: =SUMIF($K$7:$K$61,Q12,$M$7:$M$61) -> 8541.748 | T12: =SUMIF($K$7:$K$61,Q12,$N$7:$N$61) -> 29437.386 | U12: =SUMIF($K$7:$K$61,Q12,$O$7:$O$61) -> 22052.765
Q13: =Q12+1 -> 2028 | R13: =SUMIF($K$7:$K$61,Q13,$L$7:$L$61) -> 22052.765 | S13: =SUMIF($K$7:$K$61,Q13,$M$7:$M$61) -> 6785.466 | T13: =SUMIF($K$7:$K$61,Q13,$N$7:$N$61) -> 18660.032 | U13: =SUMIF($K$7:$K$61,Q13,$O$7:$O$61) -> 15267.299
B14: =B7+1 -> 2 | C14: 33927.33 | D14: 5 | E14: 46113 | F14: 46023 | G14: =YEAR(F14) -> 2026 | H14: =IF(OR(E14="",F14=""),"",(360-(E14-F14))) -> 270 | I14: =IF(OR(E14="",F14=""),"",360-H14) -> 90 | J14: =IF(OR(D14="",C14="",H14=""),"",1) -> 1 | K14: =IF(G14="","",G14) -> 2026 | L14: =IF(C14="","",C14) -> 33927.33 | M14: =IF(OR(J14="",H14=""),"",(C$14/D$14)*H14/360) -> 5089.0995 | N14: =M14 -> 5089.0995 | O14: =IF(J14="","",L14-M14) -> 28838.231 | Q14: =Q13+1 -> 2029 | R14: =SUMIF($K$7:$K$61,Q14,$L$7:$L$61) -> 15267.299 | S14: =SUMIF($K$7:$K$61,Q14,$M$7:$M$61) -> 6785.466 | T14: =SUMIF($K$7:$K$61,Q14,$N$7:$N$61) -> 25445.498 | U14: =SUMIF($K$7:$K$61,Q14,$O$7:$O$61) -> 8481.8325
J15: =IF(J14="","",IF(J14+1>D$14+1,"",J14+1)) -> 2 | K15: =IF(J15="","",K14+1) -> 2027 | L15: =IF(J15="","",L14-M14) -> 28838.231 | M15: =IF(J15="","",IF(J15=D$14+1,(C$14/D$14)*(I$14/360),C$14/D$14)) -> 6785.466 | N15: =IF(J15="","",N14+M15) -> 11874.566 | O15: =IF(J15="","",L15-M15) -> 22052.765 | Q15: =Q14+1 -> 2030 | R15: =SUMIF($K$7:$K$61,Q15,$L$7:$L$61) -> 8481.8325 | S15: =SUMIF($K$7:$K$61,Q15,$M$7:$M$61) -> 6785.466 | T15: =SUMIF($K$7:$K$61,Q15,$N$7:$N$61) -> 32230.964 | U15: =SUMIF($K$7:$K$61,Q15,$O$7:$O$61) -> 1696.3665
J16: =IF(J15="","",IF(J15+1>D$14+1,"",J15+1)) -> 3 | K16: =IF(J16="","",K15+1) -> 2028 | L16: =IF(J16="","",L15-M15) -> 22052.765 | M16: =IF(J16="","",IF(J16=D$14+1,(C$14/D$14)*(I$14/360),C$14/D$14)) -> 6785.466 | N16: =IF(J16="","",N15+M16) -> 18660.032 | O16: =IF(J16="","",L16-M16) -> 15267.299
J17: =IF(J16="","",IF(J16+1>D$14+1,"",J16+1)) -> 4 | K17: =IF(J17="","",K16+1) -> 2029 | L17: =IF(J17="","",L16-M16) -> 15267.299 | M17: =IF(J17="","",IF(J17=D$14+1,(C$14/D$14)*(I$14/360),C$14/D$14)) -> 6785.466 | N17: =IF(J17="","",N16+M17) -> 25445.498 | O17: =IF(J17="","",L17-M17) -> 8481.8325
J18: =IF(J17="","",IF(J17+1>D$14+1,"",J17+1)) -> 5 | K18: =IF(J18="","",K17+1) -> 2030 | L18: =IF(J18="","",L17-M17) -> 8481.8325 | M18: =IF(J18="","",IF(J18=D$14+1,(C$14/D$14)*(I$14/360),C$14/D$14)) -> 6785.466 | N18: =IF(J18="","",N17+M18) -> 32230.964 | O18: =IF(J18="","",L18-M18) -> 1696.3665
J19: =IF(J18="","",IF(J18+1>D$14+1,"",J18+1)) -> 6 | K19: =IF(J19="","",K18+1) -> 2031 | L19: =IF(J19="","",L18-M18) -> 1696.3665 | M19: =IF(J19="","",IF(J19=D$14+1,(C$14/D$14)*(I$14/360),C$14/D$14)) -> 1696.3665 | N19: =IF(J19="","",N18+M19) -> 33927.33 | O19: =IF(J19="","",L19-M19) -> 0
B21: =B14+1 -> 3 | G21: =YEAR(F21) -> 1900 | H21: =IF(OR(E21="",F21=""),"",(360-(E21-F21))) | I21: =IF(OR(E21="",F21=""),"",360-H21) | J21: =IF(OR(D21="",C21="",H21=""),"",1) | K21: =IF(G21="","",G21) -> 1900 | L21: =IF(C21="","",C21) | M21: =IF(OR(J21="",H21=""),"",(C$21/D$21)*H21/360) | N21: =M21 | O21: =IF(J21="","",L21-M21)
J22: =IF(J21="","",IF(J21+1>D$21+1,"",J21+1)) | K22: =IF(J22="","",K21+1) | L22: =IF(J22="","",L21-M21) | M22: =IF(J22="","",IF(J22=D$21+1,(C$21/D$21)*(I$21/360),C$21/D$21)) | N22: =IF(J22="","",N21+M22) | O22: =IF(J22="","",L22-M22)
J23: =IF(J22="","",IF(J22+1>D$21+1,"",J22+1)) | K23: =IF(J23="","",K22+1) | L23: =IF(J23="","",L22-M22) | M23: =IF(J23="","",IF(J23=D$21+1,(C$21/D$21)*(I$21/360),C$21/D$21)) | N23: =IF(J23="","",N22+M23) | O23: =IF(J23="","",L23-M23)
J24: =IF(J23="","",IF(J23+1>D$21+1,"",J23+1)) | K24: =IF(J24="","",K23+1) | L24: =IF(J24="","",L23-M23) | M24: =IF(J24="","",IF(J24=D$21+1,(C$21/D$21)*(I$21/360),C$21/D$21)) | N24: =IF(J24="","",N23+M24) | O24: =IF(J24="","",L24-M24)
J25: =IF(J24="","",IF(J24+1>D$21+1,"",J24+1)) | K25: =IF(J25="","",K24+1) | L25: =IF(J25="","",L24-M24) | M25: =IF(J25="","",IF(J25=D$21+1,(C$21/D$21)*(I$21/360),C$21/D$21)) | N25: =IF(J25="","",N24+M25) | O25: =IF(J25="","",L25-M25)
J26: =IF(J25="","",IF(J25+1>D$21+1,"",J25+1)) | K26: =IF(J26="","",K25+1) | L26: =IF(J26="","",L25-M25) | M26: =IF(J26="","",IF(J26=D$21+1,(C$21/D$21)*(I$21/360),C$21/D$21)) | N26: =IF(J26="","",N25+M26) | O26: =IF(J26="","",L26-M26)
B28: =B21+1 -> 4 | G28: =YEAR(F28) -> 1900 | H28: =IF(OR(E28="",F28=""),"",(360-(E28-F28))) | I28: =IF(OR(E28="",F28=""),"",360-H28) | J28: =IF(OR(D28="",C28="",H28=""),"",1) | K28: =IF(G28="","",G28) -> 1900 | L28: =IF(C28="","",C28) | M28: =IF(OR(J28="",H28=""),"",(C$28/D$28)*H28/360) | N28: =M28 | O28: =IF(J28="","",L28-M28)
J29: =IF(J28="","",IF(J28+1>D$28+1,"",J28+1)) | K29: =IF(J29="","",K28+1) | L29: =IF(J29="","",L28-M28) | M29: =IF(J29="","",IF(J29=D$28+1,(C$28/D$28)*(I$28/360),C$28/D$28)) | N29: =IF(J29="","",N28+M29) | O29: =IF(J29="","",L29-M29)
J30: =IF(J29="","",IF(J29+1>D$28+1,"",J29+1)) | K30: =IF(J30="","",K29+1) | L30: =IF(J30="","",L29-M29) | M30: =IF(J30="","",IF(J30=D$28+1,(C$28/D$28)*(I$28/360),C$28/D$28)) | N30: =IF(J30="","",N29+M30) | O30: =IF(J30="","",L30-M30)
J31: =IF(J30="","",IF(J30+1>D$28+1,"",J30+1)) | K31: =IF(J31="","",K30+1) | L31: =IF(J31="","",L30-M30) | M31: =IF(J31="","",IF(J31=D$28+1,(C$28/D$28)*(I$28/360),C$28/D$28)) | N31: =IF(J31="","",N30+M31) | O31: =IF(J31="","",L31-M31)
J32: =IF(J31="","",IF(J31+1>D$28+1,"",J31+1)) | K32: =IF(J32="","",K31+1) | L32: =IF(J32="","",L31-M31) | M32: =IF(J32="","",IF(J32=D$28+1,(C$28/D$28)*(I$28/360),C$28/D$28)) | N32: =IF(J32="","",N31+M32) | O32: =IF(J32="","",L32-M32)
J33: =IF(J32="","",IF(J32+1>D$28+1,"",J32+1)) | K33: =IF(J33="","",K32+1) | L33: =IF(J33="","",L32-M32) | M33: =IF(J33="","",IF(J33=D$28+1,(C$28/D$28)*(I$28/360),C$28/D$28)) | N33: =IF(J33="","",N32+M33) | O33: =IF(J33="","",L33-M33)
B35: =B28+1 -> 5 | G35: =YEAR(F35) -> 1900 | H35: =IF(OR(E35="",F35=""),"",(360-(E35-F35))) | I35: =IF(OR(E35="",F35=""),"",360-H35) | J35: =IF(OR(D35="",C35="",H35=""),"",1) | K35: =IF(G35="","",G35) -> 1900 | L35: =IF(C35="","",C35) | M35: =IF(OR(J35="",H35=""),"",(C$35/D$35)*H35/360) | N35: =M35 | O35: =IF(J35="","",L35-M35)
J36: =IF(J35="","",IF(J35+1>D$35+1,"",J35+1)) | K36: =IF(J36="","",K35+1) | L36: =IF(J36="","",L35-M35) | M36: =IF(J36="","",IF(J36=D$35+1,(C$35/D$35)*(I$35/360),C$35/D$7)) | N36: =IF(J36="","",N35+M36) | O36: =IF(J36="","",L36-M36)
J37: =IF(J36="","",IF(J36+1>D$35+1,"",J36+1)) | K37: =IF(J37="","",K36+1) | L37: =IF(J37="","",L36-M36) | M37: =IF(J37="","",IF(J37=D$35+1,(C$35/D$35)*(I$35/360),C$35/D$7)) | N37: =IF(J37="","",N36+M37) | O37: =IF(J37="","",L37-M37)
J38: =IF(J37="","",IF(J37+1>D$35+1,"",J37+1)) | K38: =IF(J38="","",K37+1) | L38: =IF(J38="","",L37-M37) | M38: =IF(J38="","",IF(J38=D$35+1,(C$35/D$35)*(I$35/360),C$35/D$7)) | N38: =IF(J38="","",N37+M38) | O38: =IF(J38="","",L38-M38)
J39: =IF(J38="","",IF(J38+1>D$35+1,"",J38+1)) | K39: =IF(J39="","",K38+1) | L39: =IF(J39="","",L38-M38) | M39: =IF(J39="","",IF(J39=D$35+1,(C$35/D$35)*(I$35/360),C$35/D$7)) | N39: =IF(J39="","",N38+M39) | O39: =IF(J39="","",L39-M39)
J40: =IF(J39="","",IF(J39+1>D$35+1,"",J39+1)) | K40: =IF(J40="","",K39+1) | L40: =IF(J40="","",L39-M39) | M40: =IF(J40="","",IF(J40=D$35+1,(C$35/D$35)*(I$35/360),C$35/D$7)) | N40: =IF(J40="","",N39+M40) | O40: =IF(J40="","",L40-M40)
B42: =B35+1 -> 6 | G42: =YEAR(F42) -> 1900 | H42: =IF(OR(E42="",F42=""),"",(360-(E42-F42))) | I42: =IF(OR(E42="",F42=""),"",360-H42) | J42: =IF(OR(D42="",C42="",H42=""),"",1) | K42: =IF(G42="","",G42) -> 1900 | L42: =IF(C42="","",C42) | M42: =IF(OR(J42="",H42=""),"",(C$42/D$42)*H42/360) | N42: =M42 | O42: =IF(J42="","",L42-M42)
J43: =IF(J42="","",IF(J42+1>D$42+1,"",J42+1)) | K43: =IF(J43="","",K42+1) | L43: =IF(J43="","",L42-M42) | M43: =IF(J43="","",IF(J43=D$42+1,(C$42/D$42)*(I$42/360),C$42/D$42)) | N43: =IF(J43="","",N42+M43) | O43: =IF(J43="","",L43-M43)
J44: =IF(J43="","",IF(J43+1>D$42+1,"",J43+1)) | K44: =IF(J44="","",K43+1) | L44: =IF(J44="","",L43-M43) | M44: =IF(J44="","",IF(J44=D$42+1,(C$42/D$42)*(I$42/360),C$42/D$42)) | N44: =IF(J44="","",N43+M44) | O44: =IF(J44="","",L44-M44)
J45: =IF(J44="","",IF(J44+1>D$42+1,"",J44+1)) | K45: =IF(J45="","",K44+1) | L45: =IF(J45="","",L44-M44) | M45: =IF(J45="","",IF(J45=D$42+1,(C$42/D$42)*(I$42/360),C$42/D$42)) | N45: =IF(J45="","",N44+M45) | O45: =IF(J45="","",L45-M45)
J46: =IF(J45="","",IF(J45+1>D$42+1,"",J45+1)) | K46: =IF(J46="","",K45+1) | L46: =IF(J46="","",L45-M45) | M46: =IF(J46="","",IF(J46=D$42+1,(C$42/D$42)*(I$42/360),C$42/D$42)) | N46: =IF(J46="","",N45+M46) | O46: =IF(J46="","",L46-M46)
J47: =IF(J46="","",IF(J46+1>D$42+1,"",J46+1)) | K47: =IF(J47="","",K46+1) | L47: =IF(J47="","",L46-M46) | M47: =IF(J47="","",IF(J47=D$42+1,(C$42/D$42)*(I$42/360),C$42/D$42)) | N47: =IF(J47="","",N46+M47) | O47: =IF(J47="","",L47-M47)
...

Sheet AMM C
C2: NEW LIFE Sàrl - Luxembourg | I2: 2025 | J2: Tableau d'Amortissement Linéaire | Q2: TOTALI
C4: MOBILIER
B6: Nr | C6: Valeur du bien | D6: Nombre années amortissement | E6: Date acquisition | F6: Date début exercise | H6: Durée utilisation 1er année | I6: Durée utilisation dernière année | J6: Nr années | K6: Année | L6: Valeur comptable début d'exercise | M6: Annuité d'amortissement | N6: Amortissements cumulés | O6: Valeur nette comptable en fin d'exercice | Q6: Année | R6: Valeur comptable début d'exercise | S6: Annuité d'amortissement | T6: Amortissements cumulés | U6: Valeur nette comptable en fin d'exercice
B7: 1 | C7: 1520 | D7: 5 | E7: 44606 | F7: 44562 | G7: =YEAR(F7) -> 2022 | H7: =IF(OR(E7="",F7=""),"",(360-(E7-F7))) -> 316 | I7: =IF(OR(E7="",F7=""),"",360-H7) -> 44 | J7: =IF(OR(D7="",C7="",H7=""),"",1) -> 1 | K7: =IF(G7="","",G7) -> 2022 | L7: =IF(C7="","",C7) -> 1520 | M7: =IF(OR(J7="",H7=""),"",(C$7/D$7)*H7/360) -> 266.84444 | N7: =M7 -> 266.84444 | O7: =IF(J7="","",L7-M7) -> 1253.1556 | Q7: 2022 | R7: =SUMIF($K$7:$K$61,Q7,$L$7:$L$61) -> 8559.04 | S7: =SUMIF($K$7:$K$61,Q7,$M$7:$M$61) -> 1174.1355 | T7: =SUMIF($K$7:$K$61,Q7,$N$7:$N$61) -> 1174.1355 | U7: =SUMIF($K$7:$K$61,Q7,$O$7:$O$61) -> 7384.9045
C8: Idrosanitaria Piave - Italie | E8: Bureautique | J8: =IF(J7="","",IF(J7+1>D$7+1,"",J7+1)) -> 2 | K8: =IF(J8="","",K7+1) -> 2023 | L8: =IF(J8="","",L7-M7) -> 1253.1556 | M8: =IF(J8="","",IF(J8=D$7+1,(C$7/D$7)*(I$7/360),C$7/D$7)) -> 304 | N8: =IF(J8="","",N7+M8) -> 570.84444 | O8: =IF(J8="","",L8-M8) -> 949.15556 | Q8: =Q7+1 -> 2023 | R8: =SUMIF($K$7:$K$61,Q8,$L$7:$L$61) -> 7384.9045 | S8: =SUMIF($K$7:$K$61,Q8,$M$7:$M$61) -> 1711.808 | T8: =SUMIF($K$7:$K$61,Q8,$N$7:$N$61) -> 2885.9435 | U8: =SUMIF($K$7:$K$61,Q8,$O$7:$O$61) -> 5673.0965
J9: =IF(J8="","",IF(J8+1>D$7+1,"",J8+1)) -> 3 | K9: =IF(J9="","",K8+1) -> 2024 | L9: =IF(J9="","",L8-M8) -> 949.15556 | M9: =IF(J9="","",IF(J9=D$7+1,(C$7/D$7)*(I$7/360),C$7/D$7)) -> 304 | N9: =IF(J9="","",N8+M9) -> 874.84444 | O9: =IF(J9="","",L9-M9) -> 645.15556 | Q9: =Q8+1 -> 2024 | R9: =SUMIF($K$7:$K$61,Q9,$L$7:$L$61) -> 5673.0965 | S9: =SUMIF($K$7:$K$61,Q9,$M$7:$M$61) -> 1711.808 | T9: =SUMIF($K$7:$K$61,Q9,$N$7:$N$61) -> 4597.7515 | U9: =SUMIF($K$7:$K$61,Q9,$O$7:$O$61) -> 3961.2885
J10: =IF(J9="","",IF(J9+1>D$7+1,"",J9+1)) -> 4 | K10: =IF(J10="","",K9+1) -> 2025 | L10: =IF(J10="","",L9-M9) -> 645.15556 | M10: =IF(J10="","",IF(J10=D$7+1,(C$7/D$7)*(I$7/360),C$7/D$7)) -> 304 | N10: =IF(J10="","",N9+M10) -> 1178.8444 | O10: =IF(J10="","",L10-M10) -> 341.15556 | Q10: =Q9+1 -> 2025 | R10: =SUMIF($K$7:$K$61,Q10,$L$7:$L$61) -> 7766.4185 | S10: =SUMIF($K$7:$K$61,Q10,$M$7:$M$61) -> 2092.321 | T10: =SUMIF($K$7:$K$61,Q10,$N$7:$N$61) -> 6690.0725 | U10: =SUMIF($K$7:$K$61,Q10,$O$7:$O$61) -> 5674.0975
J11: =IF(J10="","",IF(J10+1>D$7+1,"",J10+1)) -> 5 | K11: =IF(J11="","",K10+1) -> 2026 | L11: =IF(J11="","",L10-M10) -> 341.15556 | M11: =IF(J11="","",IF(J11=D$7+1,(C$7/D$7)*(I$7/360),C$7/D$7)) -> 304 | N11: =IF(J11="","",N10+M11) -> 1482.8444 | O11: =IF(J11="","",L11-M11) -> 37.155556 | Q11: =Q10+1 -> 2026 | R11: =SUMIF($K$7:$K$61,Q11,$L$7:$L$61) -> 5674.0975 | S11: =SUMIF($K$7:$K$61,Q11,$M$7:$M$61) -> 2472.834 | T11: =SUMIF($K$7:$K$61,Q11,$N$7:$N$61) -> 9162.9065 | U11: =SUMIF($K$7:$K$61,Q11,$O$7:$O$61) -> 3201.2635
J12: =IF(J11="","",IF(J11+1>D$7+1,"",J11+1)) -> 6 | K12: =IF(J12="","",K11+1) -> 2027 | L12: =IF(J12="","",L11-M11) -> 37.155556 | M12: =IF(J12="","",IF(J12=D$7+1,(C$7/D$7)*(I$7/360),C$7/D$7)) -> 37.155556 | N12: =IF(J12="","",N11+M12) -> 1520 | O12: =IF(J12="","",L12-M12) -> 1.4210855e-14 | Q12: =Q11+1 -> 2027 | R12: =SUMIF($K$7:$K$61,Q12,$L$7:$L$61) -> 3201.2635 | S12: =SUMIF($K$7:$K$61,Q12,$M$7:$M$61) -> 1298.6985 | T12: =SUMIF($K$7:$K$61,Q12,$N$7:$N$61) -> 10461.605 | U12: =SUMIF($K$7:$K$61,Q12,$O$7:$O$61) -> 1902.565
Q13: =Q12+1 -> 2028 | R13: =SUMIF($K$7:$K$61,Q13,$L$7:$L$61) -> 1902.565 | S13: =SUMIF($K$7:$K$61,Q13,$M$7:$M$61) -> 761.026 | T13: =SUMIF($K$7:$K$61,Q13,$N$7:$N$61) -> 2663.591 | U13: =SUMIF($K$7:$K$61,Q13,$O$7:$O$61) -> 1141.539
B14: =B7+1 -> 2 | C14: 1020 | D14: 5 | E14: 44664 | F14: 44562 | G14: =YEAR(F14) -> 2022 | H14: =IF(OR(E14="",F14=""),"",(360-(E14-F14))) -> 258 | I14: =IF(OR(E14="",F14=""),"",360-H14) -> 102 | J14: =IF(OR(D14="",C14="",H14=""),"",1) -> 1 | K14: =IF(G14="","",G14) -> 2022 | L14: =IF(C14="","",C14) -> 1020 | M14: =IF(OR(J14="",H14=""),"",(C$14/D$14)*H14/360) -> 146.2 | N14: =M14 -> 146.2 | O14: =IF(J14="","",L14-M14) -> 873.8 | Q14: =Q13+1 -> 2029 | R14: =SUMIF($K$7:$K$61,Q14,$L$7:$L$61) -> 1141.539 | S14: =SUMIF($K$7:$K$61,Q14,$M$7:$M$61) -> 761.026 | T14: =SUMIF($K$7:$K$61,Q14,$N$7:$N$61) -> 3424.617 | U14: =SUMIF($K$7:$K$61,Q14,$O$7:$O$61) -> 380.513
C15: SME S.p.A. - Italie | E15: Bureautique | J15: =IF(J14="","",IF(J14+1>D$14+1,"",J14+1)) -> 2 | K15: =IF(J15="","",K14+1) -> 2023 | L15: =IF(J15="","",L14-M14) -> 873.8 | M15: =IF(J15="","",IF(J15=D$14+1,(C$14/D$14)*(I$14/360),C$14/D$14)) -> 204 | N15: =IF(J15="","",N14+M15) -> 350.2 | O15: =IF(J15="","",L15-M15) -> 669.8 | Q15: =Q14+1 -> 2030 | R15: =SUMIF($K$7:$K$61,Q15,$L$7:$L$61) -> 380.513 | S15: =SUMIF($K$7:$K$61,Q15,$M$7:$M$61) -> 380.513 | T15: =SUMIF($K$7:$K$61,Q15,$N$7:$N$61) -> 3805.13 | U15: =SUMIF($K$7:$K$61,Q15,$O$7:$O$61) -> 1.1368684e-13
J16: =IF(J15="","",IF(J15+1>D$14+1,"",J15+1)) -> 3 | K16: =IF(J16="","",K15+1) -> 2024 | L16: =IF(J16="","",L15-M15) -> 669.8 | M16: =IF(J16="","",IF(J16=D$14+1,(C$14/D$14)*(I$14/360),C$14/D$14)) -> 204 | N16: =IF(J16="","",N15+M16) -> 554.2 | O16: =IF(J16="","",L16-M16) -> 465.8
J17: =IF(J16="","",IF(J16+1>D$14+1,"",J16+1)) -> 4 | K17: =IF(J17="","",K16+1) -> 2025 | L17: =IF(J17="","",L16-M16) -> 465.8 | M17: =IF(J17="","",IF(J17=D$14+1,(C$14/D$14)*(I$14/360),C$14/D$14)) -> 204 | N17: =IF(J17="","",N16+M17) -> 758.2 | O17: =IF(J17="","",L17-M17) -> 261.8
J18: =IF(J17="","",IF(J17+1>D$14+1,"",J17+1)) -> 5 | K18: =IF(J18="","",K17+1) -> 2026 | L18: =IF(J18="","",L17-M17) -> 261.8 | M18: =IF(J18="","",IF(J18=D$14+1,(C$14/D$14)*(I$14/360),C$14/D$14)) -> 204 | N18: =IF(J18="","",N17+M18) -> 962.2 | O18: =IF(J18="","",L18-M18) -> 57.8
J19: =IF(J18="","",IF(J18+1>D$14+1,"",J18+1)) -> 6 | K19: =IF(J19="","",K18+1) -> 2027 | L19: =IF(J19="","",L18-M18) -> 57.8 | M19: =IF(J19="","",IF(J19=D$14+1,(C$14/D$14)*(I$14/360),C$14/D$14)) -> 57.8 | N19: =IF(J19="","",N18+M19) -> 1020 | O19: =IF(J19="","",L19-M19) -> -4.2632564e-14
B21: =B14+1 -> 3 | C21: 3541.67 | D21: 5 | E21: 44681 | F21: 44562 | G21: =YEAR(F21) -> 2022 | H21: =IF(OR(E21="",F21=""),"",(360-(E21-F21))) -> 241 | I21: =IF(OR(E21="",F21=""),"",360-H21) -> 119 | J21: =IF(OR(D21="",C21="",H21=""),"",1) -> 1 | K21: =IF(G21="","",G21) -> 2022 | L21: =IF(C21="","",C21) -> 3541.67 | M21: =IF(OR(J21="",H21=""),"",(C$21/D$21)*H21/360) -> 474.19026 | N21: =M21 -> 474.19026 | O21: =IF(J21="","",L21-M21) -> 3067.4797
C22: Idrosanitaria Piave - Italie | E22: Bureautique | J22: =IF(J21="","",IF(J21+1>D$21+1,"",J21+1)) -> 2 | K22: =IF(J22="","",K21+1) -> 2023 | L22: =IF(J22="","",L21-M21) -> 3067.4797 | M22: =IF(J22="","",IF(J22=D$21+1,(C$21/D$21)*(I$21/360),C$21/D$21)) -> 708.334 | N22: =IF(J22="","",N21+M22) -> 1182.5243 | O22: =IF(J22="","",L22-M22) -> 2359.1457
J23: =IF(J22="","",IF(J22+1>D$21+1,"",J22+1)) -> 3 | K23: =IF(J23="","",K22+1) -> 2024 | L23: =IF(J23="","",L22-M22) -> 2359.1457 | M23: =IF(J23="","",IF(J23=D$21+1,(C$21/D$21)*(I$21/360),C$21/D$21)) -> 708.334 | N23: =IF(J23="","",N22+M23) -> 1890.8583 | O23: =IF(J23="","",L23-M23) -> 1650.8117
J24: =IF(J23="","",IF(J23+1>D$21+1,"",J23+1)) -> 4 | K24: =IF(J24="","",K23+1) -> 2025 | L24: =IF(J24="","",L23-M23) -> 1650.8117 | M24: =IF(J24="","",IF(J24=D$21+1,(C$21/D$21)*(I$21/360),C$21/D$21)) -> 708.334 | N24: =IF(J24="","",N23+M24) -> 2599.1923 | O24: =IF(J24="","",L24-M24) -> 942.47774
J25: =IF(J24="","",IF(J24+1>D$21+1,"",J24+1)) -> 5 | K25: =IF(J25="","",K24+1) -> 2026 | L25: =IF(J25="","",L24-M24) -> 942.47774 | M25: =IF(J25="","",IF(J25=D$21+1,(C$21/D$21)*(I$21/360),C$21/D$21)) -> 708.334 | N25: =IF(J25="","",N24+M25) -> 3307.5263 | O25: =IF(J25="","",L25-M25) -> 234.14374
J26: =IF(J25="","",IF(J25+1>D$21+1,"",J25+1)) -> 6 | K26: =IF(J26="","",K25+1) -> 2027 | L26: =IF(J26="","",L25-M25) -> 234.14374 | M26: =IF(J26="","",IF(J26=D$21+1,(C$21/D$21)*(I$21/360),C$21/D$21)) -> 234.14374 | N26: =IF(J26="","",N25+M26) -> 3541.67 | O26: =IF(J26="","",L26-M26) -> 2.8421709e-13
B28: =B21+1 -> 4 | C28: 1403.31 | D28: 5 | E28: 44691 | F28: 44562 | G28: =YEAR(F28) -> 2022 | H28: =IF(OR(E28="",F28=""),"",(360-(E28-F28))) -> 231 | I28: =IF(OR(E28="",F28=""),"",360-H28) -> 129 | J28: =IF(OR(D28="",C28="",H28=""),"",1) -> 1 | K28: =IF(G28="","",G28) -> 2022 | L28: =IF(C28="","",C28) -> 1403.31 | M28: =IF(OR(J28="",H28=""),"",(C$28/D$28)*H28/360) -> 180.09145 | N28: =M28 -> 180.09145 | O28: =IF(J28="","",L28-M28) -> 1223.2186
C29: IKEA Arlon - Belgique | E29: Bureautique | J29: =IF(J28="","",IF(J28+1>D$28+1,"",J28+1)) -> 2 | K29: =IF(J29="","",K28+1) -> 2023 | L29: =IF(J29="","",L28-M28) -> 1223.2186 | M29: =IF(J29="","",IF(J29=D$28+1,(C$28/D$28)*(I$28/360),C$28/D$28)) -> 280.662 | N29: =IF(J29="","",N28+M29) -> 460.75345 | O29: =IF(J29="","",L29-M29) -> 942.55655
J30: =IF(J29="","",IF(J29+1>D$28+1,"",J29+1)) -> 3 | K30: =IF(J30="","",K29+1) -> 2024 | L30: =IF(J30="","",L29-M29) -> 942.55655 | M30: =IF(J30="","",IF(J30=D$28+1,(C$28/D$28)*(I$28/360),C$28/D$28)) -> 280.662 | N30: =IF(J30="","",N29+M30) -> 741.41545 | O30: =IF(J30="","",L30-M30) -> 661.89455
J31: =IF(J30="","",IF(J30+1>D$28+1,"",J30+1)) -> 4 | K31: =IF(J31="","",K30+1) -> 2025 | L31: =IF(J31="","",L30-M30) -> 661.89455 | M31: =IF(J31="","",IF(J31=D$28+1,(C$28/D$28)*(I$28/360),C$28/D$28)) -> 280.662 | N31: =IF(J31="","",N30+M31) -> 1022.0774 | O31: =IF(J31="","",L31-M31) -> 381.23255
J32: =IF(J31="","",IF(J31+1>D$28+1,"",J31+1)) -> 5 | K32: =IF(J32="","",K31+1) -> 2026 | L32: =IF(J32="","",L31-M31) -> 381.23255 | M32: =IF(J32="","",IF(J32=D$28+1,(C$28/D$28)*(I$28/360),C$28/D$28)) -> 280.662 | N32: =IF(J32="","",N31+M32) -> 1302.7395 | O32: =IF(J32="","",L32-M32) -> 100.57055
J33: =IF(J32="","",IF(J32+1>D$28+1,"",J32+1)) -> 6 | K33: =IF(J33="","",K32+1) -> 2027 | L33: =IF(J33="","",L32-M32) -> 100.57055 | M33: =IF(J33="","",IF(J33=D$28+1,(C$28/D$28)*(I$28/360),C$28/D$28)) -> 100.57055 | N33: =IF(J33="","",N32+M33) -> 1403.31 | O33: =IF(J33="","",L33-M33) -> 2.8421709e-14
B35: =B28+1 -> 5 | C35: 1074.06 | D35: 5 | E35: 44743 | F35: 44562 | G35: =YEAR(F35) -> 2022 | H35: =IF(OR(E35="",F35=""),"",(360-(E35-F35))) -> 179 | I35: =IF(OR(E35="",F35=""),"",360-H35) -> 181 | J35: =IF(OR(D35="",C35="",H35=""),"",1) -> 1 | K35: =IF(G35="","",G35) -> 2022 | L35: =IF(C35="","",C35) -> 1074.06 | M35: =IF(OR(J35="",H35=""),"",(C$35/D$35)*H35/360) -> 106.8093 | N35: =M35 -> 106.8093 | O35: =IF(J35="","",L35-M35) -> 967.2507
C36: Idrosanitaria Piave - Italie | E36: Bureautique | J36: =IF(J35="","",IF(J35+1>D$35+1,"",J35+1)) -> 2 | K36: =IF(J36="","",K35+1) -> 2023 | L36: =IF(J36="","",L35-M35) -> 967.2507 | M36: =IF(J36="","",IF(J36=D$35+1,(C$35/D$35)*(I$35/360),C$35/D$7)) -> 214.812 | N36: =IF(J36="","",N35+M36) -> 321.6213 | O36: =IF(J36="","",L36-M36) -> 752.4387
J37: =IF(J36="","",IF(J36+1>D$35+1,"",J36+1)) -> 3 | K37: =IF(J37="","",K36+1) -> 2024 | L37: =IF(J37="","",L36-M36) -> 752.4387 | M37: =IF(J37="","",IF(J37=D$35+1,(C$35/D$35)*(I$35/360),C$35/D$7)) -> 214.812 | N37: =IF(J37="","",N36+M37) -> 536.4333 | O37: =IF(J37="","",L37-M37) -> 537.6267
J38: =IF(J37="","",IF(J37+1>D$35+1,"",J37+1)) -> 4 | K38: =IF(J38="","",K37+1) -> 2025 | L38: =IF(J38="","",L37-M37) -> 537.6267 | M38: =IF(J38="","",IF(J38=D$35+1,(C$35/D$35)*(I$35/360),C$35/D$7)) -> 214.812 | N38: =IF(J38="","",N37+M38) -> 751.2453 | O38: =IF(J38="","",L38-M38) -> 322.8147
J39: =IF(J38="","",IF(J38+1>D$35+1,"",J38+1)) -> 5 | K39: =IF(J39="","",K38+1) -> 2026 | L39: =IF(J39="","",L38-M38) -> 322.8147 | M39: =IF(J39="","",IF(J39=D$35+1,(C$35/D$35)*(I$35/360),C$35/D$7)) -> 214.812 | N39: =IF(J39="","",N38+M39) -> 966.0573 | O39: =IF(J39="","",L39-M39) -> 108.0027
J40: =IF(J39="","",IF(J39+1>D$35+1,"",J39+1)) -> 6 | K40: =IF(J40="","",K39+1) -> 2027 | L40: =IF(J40="","",L39-M39) -> 108.0027 | M40: =IF(J40="","",IF(J40=D$35+1,(C$35/D$35)*(I$35/360),C$35/D$7)) -> 108.0027 | N40: =IF(J40="","",N39+M40) -> 1074.06 | O40: =IF(J40="","",L40-M40) -> -7.1054274e-14
B42: =B35+1 -> 6 | C42: 3805.13 | D42: 5 | E42: 45839 | F42: 45658 | G42: =YEAR(F42) -> 2025 | H42: 180 | I42: 180 | J42: =IF(OR(D42="",C42="",H42=""),"",1) -> 1 | K42: =IF(G42="","",G42) -> 2025 | L42: =IF(C42="","",C42) -> 3805.13 | M42: =IF(OR(J42="",H42=""),"",(C$42/D$42)*H42/360) -> 380.513 | N42: =M42 -> 380.513 | O42: =IF(J42="","",L42-M42) -> 3424.617
C43: Hornbach - Luxembourg | J43: =IF(J42="","",IF(J42+1>D$42+1,"",J42+1)) -> 2 | K43: =IF(J43="","",K42+1) -> 2026 | L43: =IF(J43="","",L42-M42) -> 3424.617 | M43: =IF(J43="","",IF(J43=D$42+1,(C$42/D$42)*(I$42/360),C$42/D$42)) -> 761.026 | N43: =IF(J43="","",N42+M43) -> 1141.539 | O43: =IF(J43="","",L43-M43) -> 2663.591
J44: =IF(J43="","",IF(J43+1>D$42+1,"",J43+1)) -> 3 | K44: =IF(J44="","",K43+1) -> 2027 | L44: =IF(J44="","",L43-M43) -> 2663.591 | M44: =IF(J44="","",IF(J44=D$42+1,(C$42/D$42)*(I$42/360),C$42/D$42)) -> 761.026 | N44: =IF(J44="","",N43+M44) -> 1902.565 | O44: =IF(J44="","",L44-M44) -> 1902.565
J45: =IF(J44="","",IF(J44+1>D$42+1,"",J44+1)) -> 4 | K45: =IF(J45="","",K44+1) -> 2028 | L45: =IF(J45="","",L44-M44) -> 1902.565 | M45: =IF(J45="","",IF(J45=D$42+1,(C$42/D$42)*(I$42/360),C$42/D$42)) -> 761.026 | N45: =IF(J45="","",N44+M45) -> 2663.591 | O45: =IF(J45="","",L45-M45) -> 1141.539
J46: =IF(J45="","",IF(J45+1>D$42+1,"",J45+1)) -> 5 | K46: =IF(J46="","",K45+1) -> 2029 | L46: =IF(J46="","",L45-M45) -> 1141.539 | M46: =IF(J46="","",IF(J46=D$42+1,(C$42/D$42)*(I$42/360),C$42/D$42)) -> 761.026 | N46: =IF(J46="","",N45+M46) -> 3424.617 | O46: =IF(J46="","",L46-M46) -> 380.513
J47: =IF(J46="","",IF(J46+1>D$42+1,"",J46+1)) -> 6 | K47: =IF(J47="","",K46+1) -> 2030 | L47: =IF(J47="","",L46-M46) -> 380.513 | M47: =IF(J47="","",IF(J47=D$42+1,(C$42/D$42)*(I$42/360),C$42/D$42)) -> 380.513 | N47: =IF(J47="","",N46+M47) -> 3805.13 | O47: =IF(J47="","",L47-M47) -> 1.1368684e-13
...

Sheet AMM A,B,C
B2: NEW LIFE Sàrl - Luxembourg | G2: 2025 | I2: TOTAUX
B4: 21 - IMMOBILISATIONS INCORPORELLES | I4: 21 - IMMOBILISATIONS INCORPORELLES
B5: 211 - FRAIS DE DEVELOPPEMENT
B6: Année | C6: Valeur comptable début d'exercise | D6: Annuité d'amortissement | E6: Amortissements cumulés | F6: Valeur nette comptable en fin d'exercice | G6: Valeur nette comptable en fin d'exercice | I6: Année | J6: Valeur comptable début d'exercise | K6: Annuité d'amortissement | L6: Amortissements cumulés | M6: Valeur nette comptable en fin d'exercice
B7: ='AMM A'!Q7 -> 2022 | C7: ='AMM A'!R7 -> 0 | D7: ='AMM A'!S7 -> 0 | E7: ='AMM A'!T7 -> 0 | F7: =SUMIF($I$21:$I$64,B7,$M$21:$M$64) -> 23191.443 | G7: ='AMM A'!U7 -> 0 | I7: 2022 | J7: =C7 -> 0 | K7: =D7 -> 0 | L7: =E7 -> 0 | M7: =G7 -> 0
B8: ='AMM A'!Q8 -> 2023 | C8: ='AMM A'!R8 -> 4391.65 | D8: ='AMM A'!S8 -> 195.97162 | E8: ='AMM A'!T8 -> 195.97162 | F8: =SUMIF($I$21:$I$64,B8,$M$21:$M$64) -> 40129.819 | G8: ='AMM A'!U8 -> 4195.6784 | I8: 2023 | J8: =C8 -> 4391.65 | K8: =D8 -> 195.97162 | L8: =E8 -> 195.97162 | M8: =G8 -> 4195.6784
B9: ='AMM A'!Q9 -> 2024 | C9: ='AMM A'!R9 -> 7198.9384 | D9: ='AMM A'!S9 -> 2161.8632 | E9: ='AMM A'!T9 -> 2357.8348 | F9: =SUMIF($I$21:$I$64,B9,$M$21:$M$64) -> 30522.472 | G9: ='AMM A'!U9 -> 5037.0752 | I9: 2024 | J9: =C9 -> 7198.9384 | K9: =D9 -> 2161.8632 | L9: =E9 -> 2357.8348 | M9: =G9 -> 5037.0752
B10: ='AMM A'!Q10 -> 2025 | C10: ='AMM A'!R10 -> 5037.0752 | D10: ='AMM A'!S10 -> 2464.97 | E10: ='AMM A'!T10 -> 4822.8048 | F10: =SUMIF($I$21:$I$64,B10,$M$21:$M$64) -> 24457.992 | G10: ='AMM A'!U10 -> 2572.1052 | I10: 2025 | J10: =C10 -> 5037.0752 | K10: =D10 -> 2464.97 | L10: =E10 -> 4822.8048 | M10: =G10 -> 2572.1052
B11: ='AMM A'!Q11 -> 2026 | C11: ='AMM A'!R11 -> 2572.1052 | D11: ='AMM A'!S11 -> 2268.9984 | E11: ='AMM A'!T11 -> 7091.8032 | F11: =SUMIF($I$21:$I$64,B11,$M$21:$M$64) -> 67894.659 | G11: ='AMM A'!U11 -> 303.1068 | I11: 2026 | J11: =C11 -> 2572.1052 | K11: =D11 -> 2268.9984 | L11: =E11 -> 7091.8032 | M11: =G11 -> 303.1068
B12: ='AMM A'!Q12 -> 2027 | C12: ='AMM A'!R12 -> 303.1068 | D12: ='AMM A'!S12 -> 303.1068 | E12: ='AMM A'!T12 -> 3003.26 | F12: =SUMIF($I$21:$I$64,B12,$M$21:$M$64) -> 47910.659 | G12: ='AMM A'!U12 -> 1.7053026e-13 | I12: 2027 | J12: =C12 -> 303.1068 | K12: =D12 -> 303.1068 | L12: =E12 -> 3003.26 | M12: =G12 -> 1.7053026e-13
B13: ='AMM A'!Q13 -> 2028 | C13: ='AMM A'!R13 -> 0 | D13: ='AMM A'!S13 -> 0 | E13: ='AMM A'!T13 -> 0 | F13: =SUMIF($I$21:$I$64,B13,$M$21:$M$64) -> 32817.675 | G13: ='AMM A'!U13 -> 0 | I13: 2028 | J13: =C13 -> 0 | K13: =D13 -> 0 | L13: =E13 -> 0 | M13: =G13 -> 0
B14: ='AMM A'!Q14 -> 2029 | C14: ='AMM A'!R14 -> 0 | D14: ='AMM A'!S14 -> 0 | E14: ='AMM A'!T14 -> 0 | F14: =SUMIF($I$21:$I$64,B14,$M$21:$M$64) -> 17724.691 | G14: ='AMM A'!U14 -> 0 | I14: 2029 | J14: =C14 -> 0 | K14: =D14 -> 0 | L14: =E14 -> 0 | M14: =G14 -> 0
B15: ='AMM A'!Q15 -> 2030 | C15: ='AMM A'!R15 -> 0 | D15: ='AMM A'!S15 -> 0 | E15: ='AMM A'!T15 -> 0 | F15: =SUMIF($I$21:$I$64,B15,$M$21:$M$64) -> 3392.733 | G15: ='AMM A'!U15 -> 0 | I15: 2030 | J15: =C15 -> 0 | K15: =D15 -> 0 | L15: =E15 -> 0 | M15: =G15 -> 0
B17: 22 - IMMOBILISATIONS CORPORELLES | I17: 22 - IMMOBILISATIONS CORPORELLES
B18: 2232 - VEHICULES DE TRANSPORT
B19: Année | C19: Valeur comptable début d'exercise | D19: Annuité d'amortissement | E19: Amortissements cumulés | F19: Valeur nette comptable en fin d'exercice | G19: Valeur nette comptable en fin d'exercice | I19: Année | J19: Valeur comptable début d'exercise | K19: Annuité d'amortissement | L19: Amortissements cumulés | M19: Valeur nette comptable en fin d'exercice
B20: ='AMM B'!Q7 -> 2022 | C20: ='AMM B'!R7 -> 17562.82 | D20: ='AMM B'!S7 -> 1756.282 | E20: ='AMM B'!T7 -> 1756.282 | F20: =SUMIF($I$21:$I$64,B20,$M$21:$M$64) -> 23191.443 | G20: ='AMM B'!U7 -> 15806.538 | I20: 2022 | J20: =C33+C20 -> 26121.86 | K20: =D33+D20 -> 2930.4175 | L20: =E33+E20 -> 2930.4175 | M20: =G33+G20 -> 23191.443
B21: ='AMM B'!Q8 -> 2023 | C21: ='AMM B'!R8 -> 15806.538 | D21: ='AMM B'!S8 -> 3512.564 | E21: ='AMM B'!T8 -> 5268.846 | F21: =SUMIF($I$21:$I$64,B21,$M$21:$M$64) -> 40129.819 | G21: ='AMM B'!U8 -> 12293.974 | I21: 2023 | J21: =C34+C21 -> 23191.443 | K21: =D34+D21 -> 5224.372 | L21: =E34+E21 -> 8154.7895 | M21: =G34+G21 -> 17967.071
B22: ='AMM B'!Q9 -> 2024 | C22: ='AMM B'!R9 -> 12293.974 | D22: ='AMM B'!S9 -> 3512.564 | E22: ='AMM B'!T9 -> 8781.41 | F22: =SUMIF($I$21:$I$64,B22,$M$21:$M$64) -> 30522.472 | G22: ='AMM B'!U9 -> 8781.41 | I22: 2024 | J22: =C35+C22 -> 17967.071 | K22: =D35+D22 -> 5224.372 | L22: =E35+E22 -> 13379.161 | M22: =G35+G22 -> 12742.699
B23: ='AMM B'!Q10 -> 2025 | C23: ='AMM B'!R10 -> 8781.41 | D23: ='AMM B'!S10 -> 3512.564 | E23: ='AMM B'!T10 -> 12293.974 | F23: =SUMIF($I$21:$I$64,B23,$M$21:$M$64) -> 24457.992 | G23: ='AMM B'!U10 -> 5268.846 | I23: 2025 | J23: =C36+C23 -> 16547.829 | K23: =D36+D23 -> 5604.885 | L23: =E36+E23 -> 18984.046 | M23: =G36+G23 -> 10942.944
B24: ='AMM B'!Q11 -> 2026 | C24: ='AMM B'!R11 -> 39196.176 | D24: ='AMM B'!S11 -> 8601.6635 | E24: ='AMM B'!T11 -> 20895.638 | F24: =SUMIF($I$21:$I$64,B24,$M$21:$M$64) -> 67894.659 | G24: ='AMM B'!U11 -> 30594.513 | I24: 2026 | J24: =C37+C24 -> 44870.274 | K24: =D37+D24 -> 11074.498 | L24: =E37+E24 -> 30058.544 | M24: =G37+G24 -> 33795.776
B25: ='AMM B'!Q12 -> 2027 | C25: ='AMM B'!R12 -> 30594.513 | D25: ='AMM B'!S12 -> 8541.748 | E25: ='AMM B'!T12 -> 29437.386 | F25: =SUMIF($I$21:$I$64,B25,$M$21:$M$64) -> 47910.659 | G25: ='AMM B'!U12 -> 22052.765 | I25: 2027 | J25: =C38+C25 -> 33795.776 | K25: =D38+D25 -> 9840.4465 | L25: =E38+E25 -> 39898.99 | M25: =G38+G25 -> 23955.329
